[2025-04-29 15:16:41,205] {{taskinstance.py:655}} INFO - Dependencies all met for <TaskInstance: nifi_fetch_processor.fetch_nifi_processor 2025-04-29T15:16:35.258312+00:00 [queued]>
[2025-04-29 15:16:41,220] {{taskinstance.py:655}} INFO - Dependencies all met for <TaskInstance: nifi_fetch_processor.fetch_nifi_processor 2025-04-29T15:16:35.258312+00:00 [queued]>
[2025-04-29 15:16:41,221] {{taskinstance.py:866}} INFO - 
--------------------------------------------------------------------------------
[2025-04-29 15:16:41,222] {{taskinstance.py:867}} INFO - Starting attempt 1 of 1
[2025-04-29 15:16:41,223] {{taskinstance.py:868}} INFO - 
--------------------------------------------------------------------------------
[2025-04-29 15:16:41,295] {{taskinstance.py:887}} INFO - Executing <Task(PythonOperator): fetch_nifi_processor> on 2025-04-29T15:16:35.258312+00:00
[2025-04-29 15:16:41,300] {{standard_task_runner.py:53}} INFO - Started process 1317 to run task
[2025-04-29 15:16:41,433] {{logging_mixin.py:112}} INFO - Running %s on host %s <TaskInstance: nifi_fetch_processor.fetch_nifi_processor 2025-04-29T15:16:35.258312+00:00 [running]> myairflow
[2025-04-29 15:16:41,471] {{logging_mixin.py:112}} INFO - [2025-04-29 15:16:41,470] {{base_hook.py:84}} INFO - Using connection to: id: mynifi_connection. Host: http://mynifi, Port: 8080, Schema: None, Login: None, Password: None, extra: None
[2025-04-29 15:16:49,360] {{taskinstance.py:1128}} ERROR - HTTPConnectionPool(host='http', port=80): Max retries exceeded with url: //mynifi:8080/nifi-api/processors/7868e8bb-0196-1000-ffff-ffffa9f43183 (Caused by NewConnectionError('<urllib3.connection.HTTPConnection object at 0x7f133270c450>: Failed to establish a new connection: [Errno -2] Name or service not known'))
Traceback (most recent call last):
  File "/usr/local/lib/python3.7/site-packages/urllib3/connection.py", line 157, in _new_conn
    (self._dns_host, self.port), self.timeout, **extra_kw
  File "/usr/local/lib/python3.7/site-packages/urllib3/util/connection.py", line 61, in create_connection
    for res in socket.getaddrinfo(host, port, family, socket.SOCK_STREAM):
  File "/usr/local/lib/python3.7/socket.py", line 752, in getaddrinfo
    for res in _socket.getaddrinfo(host, port, family, type, proto, flags):
socket.gaierror: [Errno -2] Name or service not known

During handling of the above exception, another exception occurred:

Traceback (most recent call last):
  File "/usr/local/lib/python3.7/site-packages/urllib3/connectionpool.py", line 672, in urlopen
    chunked=chunked,
  File "/usr/local/lib/python3.7/site-packages/urllib3/connectionpool.py", line 387, in _make_request
    conn.request(method, url, **httplib_request_kw)
  File "/usr/local/lib/python3.7/http/client.py", line 1252, in request
    self._send_request(method, url, body, headers, encode_chunked)
  File "/usr/local/lib/python3.7/http/client.py", line 1298, in _send_request
    self.endheaders(body, encode_chunked=encode_chunked)
  File "/usr/local/lib/python3.7/http/client.py", line 1247, in endheaders
    self._send_output(message_body, encode_chunked=encode_chunked)
  File "/usr/local/lib/python3.7/http/client.py", line 1026, in _send_output
    self.send(msg)
  File "/usr/local/lib/python3.7/http/client.py", line 966, in send
    self.connect()
  File "/usr/local/lib/python3.7/site-packages/urllib3/connection.py", line 184, in connect
    conn = self._new_conn()
  File "/usr/local/lib/python3.7/site-packages/urllib3/connection.py", line 169, in _new_conn
    self, "Failed to establish a new connection: %s" % e
urllib3.exceptions.NewConnectionError: <urllib3.connection.HTTPConnection object at 0x7f133270c450>: Failed to establish a new connection: [Errno -2] Name or service not known

During handling of the above exception, another exception occurred:

Traceback (most recent call last):
  File "/usr/local/lib/python3.7/site-packages/requests/adapters.py", line 449, in send
    timeout=timeout
  File "/usr/local/lib/python3.7/site-packages/urllib3/connectionpool.py", line 720, in urlopen
    method, url, error=e, _pool=self, _stacktrace=sys.exc_info()[2]
  File "/usr/local/lib/python3.7/site-packages/urllib3/util/retry.py", line 436, in increment
    raise MaxRetryError(_pool, url, error or ResponseError(cause))
urllib3.exceptions.MaxRetryError: HTTPConnectionPool(host='http', port=80): Max retries exceeded with url: //mynifi:8080/nifi-api/processors/7868e8bb-0196-1000-ffff-ffffa9f43183 (Caused by NewConnectionError('<urllib3.connection.HTTPConnection object at 0x7f133270c450>: Failed to establish a new connection: [Errno -2] Name or service not known'))

During handling of the above exception, another exception occurred:

Traceback (most recent call last):
  File "/usr/local/lib/python3.7/site-packages/airflow/models/taskinstance.py", line 966, in _run_raw_task
    result = task_copy.execute(context=context)
  File "/usr/local/lib/python3.7/site-packages/airflow/operators/python_operator.py", line 113, in execute
    return_value = self.execute_callable()
  File "/usr/local/lib/python3.7/site-packages/airflow/operators/python_operator.py", line 118, in execute_callable
    return self.python_callable(*self.op_args, **self.op_kwargs)
  File "/usr/local/airflow/dags/nifi_dags.py", line 20, in fetch_processor_details
    response = requests.get(url)
  File "/usr/local/lib/python3.7/site-packages/requests/api.py", line 75, in get
    return request('get', url, params=params, **kwargs)
  File "/usr/local/lib/python3.7/site-packages/requests/api.py", line 60, in request
    return session.request(method=method, url=url, **kwargs)
  File "/usr/local/lib/python3.7/site-packages/requests/sessions.py", line 533, in request
    resp = self.send(prep, **send_kwargs)
  File "/usr/local/lib/python3.7/site-packages/requests/sessions.py", line 646, in send
    r = adapter.send(request, **kwargs)
  File "/usr/local/lib/python3.7/site-packages/requests/adapters.py", line 516, in send
    raise ConnectionError(e, request=request)
requests.exceptions.ConnectionError: HTTPConnectionPool(host='http', port=80): Max retries exceeded with url: //mynifi:8080/nifi-api/processors/7868e8bb-0196-1000-ffff-ffffa9f43183 (Caused by NewConnectionError('<urllib3.connection.HTTPConnection object at 0x7f133270c450>: Failed to establish a new connection: [Errno -2] Name or service not known'))
[2025-04-29 15:16:49,428] {{taskinstance.py:1185}} INFO - Marking task as FAILED.dag_id=nifi_fetch_processor, task_id=fetch_nifi_processor, execution_date=20250429T151635, start_date=20250429T151641, end_date=20250429T151649
[2025-04-29 15:16:51,095] {{logging_mixin.py:112}} INFO - [2025-04-29 15:16:51,095] {{local_task_job.py:103}} INFO - Task exited with return code 1
